<?xml version="1.0"?>
<robot name="cartpole" xmlns:xacro="http://ros.org/wiki/xacro">

  <link name="world"/>

  <link name="slideBar">
    <visual>
      <geometry>
        <box size="30 0.05 0.05"/>
      </geometry>
      <origin xyz="0 0 0"/>
      <material name="green">
        <color rgba="0 0.8 .8 1"/>
      </material>
    </visual>
    <inertial>
      <mass value="100"/>
      <inertia ixx="1.0" ixy="0.0" ixz="0.0" iyy="1.0" iyz="0.0" izz="1.0"/>
    </inertial>
  </link>

  <link name="cart">
    <visual>
      <geometry>
        <box size="0.5 0.5 0.2"/>
      </geometry>
      <origin xyz="0 0 0"/>
      <material name="blue">
        <color rgba="0 0 .8 1"/>
      </material>
    </visual>
    <inertial>
      <mass value="1"/>
      <inertia ixx="1.0" ixy="0.0" ixz="0.0" iyy="1.0" iyz="0.0" izz="1.0"/>
    </inertial>
  </link>

  <joint name="world_to_base" type="fixed">
    <origin xyz="0 0 1" rpy="0 0 0"/>
    <parent link="world"/>
    <child link="slideBar"/>
  </joint>

  <joint name="slider_to_cart" type="prismatic">
    <axis xyz="1 0 0"/>
    <origin xyz="0.0 0.0 0.0"/>
    <parent link="slideBar"/>
    <child link="cart"/>
    <limit effort="1000.0" lower="-15" upper="15" velocity="30"/>
    <dynamics damping="0.0" friction="0.0" />
  </joint>

  <link name="pole">
    <visual>
      <geometry>
        <box size="0.05 0.05 1.0"/>
      </geometry>
      <origin rpy="0 0 0" xyz="0 0 0.5"/>
      <material name="white">
        <color rgba="1 1 1 1"/>
      </material>
    </visual>
    <inertial>
    <origin xyz="0 0 0.5"/>
      <mass value="10"/>
      <inertia ixx="1.0" ixy="0.0" ixz="0.0" iyy="1.0" iyz="0.0" izz="1.0"/>
    </inertial>
  </link>

  <joint name="cart_to_pole" type="continuous">
    <axis xyz="0 1 0"/>
    <origin xyz="0.0 0.0 0"/>
    <parent link="cart"/>
    <child link="pole"/>
    <dynamics damping="0.0" friction="0.0" />
  </joint>

  <ros2_control name="GazeboSimSystem" type="system">
    <hardware>
      <plugin>gz_ros2_control/GazeboSimSystem</plugin>
    </hardware>

    <joint name="slider_to_cart">
      <command_interface name="velocity">
        <param name="min">-15.0</param>
        <param name="max">15.0</param>
      </command_interface>
      <state_interface name="position"/>
      <state_interface name="velocity"/>
    </joint>

    <joint name="cart_to_pole">
      <state_interface name="position"/>
      <state_interface name="velocity"/>
    </joint>
  </ros2_control>


  <gazebo>
    <plugin filename="libgz_ros2_control-system"
            name="gz_ros2_control::GazeboSimROS2ControlPlugin">
      <parameters>$(find cartpole_ros)/urdf/config/cartpole_manager.yaml</parameters>
      <controller_manager_prefix_node_name>cartpole_manager</controller_manager_prefix_node_name>
    </plugin>
  </gazebo>

</robot>